Workbook

Sheet SWOR_PA_PVT
A1: Count | B1: Plant Association | C1: Potential Vegetation Type | D1: Potential Natural Vegetation | E1: Existing Vegetation Type | F1: Biophysical Setting (BpS) | G1: BpS Name | H1: Latin plant association | I1: English plant association
A2: 1 | B2: ABAM/ROGY/ACTR | C2: Pacific silver fir - Intermediate | F2: 711740 | G2: North Pacific Dry-Mesic Silver Fir-Western Hemlock-Douglas-fir Forest | I2: =_xlfn.XLOOKUP(B2,RA_LFBpS_SWO_PAG_PA!B:B,RA_LFBpS_SWO_PAG_PA!C:C) -> Pacific Silver Fir/Vanillaleaf-Coolwort Foamflower - mesic
A3: 11 | B3: ABAM/VAAL/POMU | C3: Pacific silver fir - Intermediate | F3: 711740 | G3: North Pacific Dry-Mesic Silver Fir-Western Hemlock-Douglas-fir Forest | I3: =_xlfn.XLOOKUP(B3,RA_LFBpS_SWO_PAG_PA!B:B,RA_LFBpS_SWO_PAG_PA!C:C) -> #N/A
A4: 3 | B4: ABAM/VAME | C4: Pacific silver fir - Intermediate | F4: 711740 | G4: North Pacific Dry-Mesic Silver Fir-Western Hemlock-Douglas-fir Forest | I4: =_xlfn.XLOOKUP(B4,RA_LFBpS_SWO_PAG_PA!B:B,RA_LFBpS_SWO_PAG_PA!C:C) -> #N/A
A5: 4 | B5: ABAM/VAME/CLUN | C5: Pacific silver fir - Intermediate | F5: 711740 | G5: North Pacific Dry-Mesic Silver Fir-Western Hemlock-Douglas-fir Forest | I5: =_xlfn.XLOOKUP(B5,RA_LFBpS_SWO_PAG_PA!B:B,RA_LFBpS_SWO_PAG_PA!C:C) -> #N/A
A6: 5 | B6: ABAM/VAME/XETE | C6: Pacific silver fir - Intermediate | F6: 711740 | G6: North Pacific Dry-Mesic Silver Fir-Western Hemlock-Douglas-fir Forest | I6: =_xlfn.XLOOKUP(B6,RA_LFBpS_SWO_PAG_PA!B:B,RA_LFBpS_SWO_PAG_PA!C:C) -> #N/A
A7: 6 | B7: ABAM-TSHE/CLUN | C7: Pacific silver fir - Intermediate | F7: 711740 | G7: North Pacific Dry-Mesic Silver Fir-Western Hemlock-Douglas-fir Forest | I7: =_xlfn.XLOOKUP(B7,RA_LFBpS_SWO_PAG_PA!B:B,RA_LFBpS_SWO_PAG_PA!C:C) -> #N/A
A8: 7 | B8: ABAM-TSHE/VAME/ACTR | C8: Pacific silver fir - Intermediate | F8: 711740 | G8: North Pacific Dry-Mesic Silver Fir-Western Hemlock-Douglas-fir Forest | I8: =_xlfn.XLOOKUP(B8,RA_LFBpS_SWO_PAG_PA!B:B,RA_LFBpS_SWO_PAG_PA!C:C) -> Pacific Silver Fir/Vanillaleaf-Coolwort Foamflower - mesic
A9: 8 | B9: ABAM-TSME/VAME/ACTR | C9: Pacific silver fir - Intermediate | F9: 711740 | G9: North Pacific Dry-Mesic Silver Fir-Western Hemlock-Douglas-fir Forest | I9: =_xlfn.XLOOKUP(B9,RA_LFBpS_SWO_PAG_PA!B:B,RA_LFBpS_SWO_PAG_PA!C:C) -> Pacific Silver Fir/Big Huckleberry/Beargrass
A10: 1 | B10: ABCO, ABGR | C10: White fir - Cool | F10: 710280 | G10: Mediterranean California Mesic Mixed Conifer Forest and Woodland | I10: White fir
A11: 2 | B11: ABCO/ACCI/OXOR | C11: White fir - Cool | F11: 710280 | G11: Mediterranean California Mesic Mixed Conifer Forest and Woodland | I11: =_xlfn.XLOOKUP(B11,RA_LFBpS_SWO_PAG_PA!B:B,RA_LFBpS_SWO_PAG_PA!C:C) -> White Fir/Pacific Rhododendron
A12: 1 | B12: ABCO/ARNE | C12: White fir - Intermediate | F12: 710280 | G12: Mediterranean California Mesic Mixed Conifer Forest and Woodland | I12: =_xlfn.XLOOKUP(B12,RA_LFBpS_SWO_PAG_PA!B:B,RA_LFBpS_SWO_PAG_PA!C:C) -> White Fir - cool, dry
A13: 3 | B13: ABCO/BENE2 | C13: White fir - Intermediate | F13: 710280 | G13: Mediterranean California Mesic Mixed Conifer Forest and Woodland | I13: =_xlfn.XLOOKUP(B13,RA_LFBpS_SWO_PAG_PA!B:B,RA_LFBpS_SWO_PAG_PA!C:C) -> White Fir/Dwarf Oregongrape
A14: 5 | B14: ABCO/BENE2/ACTR | C14: White fir - Intermediate | F14: 710280 | G14: Mediterranean California Mesic Mixed Conifer Forest and Woodland | I14: =_xlfn.XLOOKUP(B14,RA_LFBpS_SWO_PAG_PA!B:B,RA_LFBpS_SWO_PAG_PA!C:C) -> White Fir/Dwarf Oregongrape
A15: 1 | B15: ABCO/BENE2/LIBOL | C15: White fir - Intermediate | F15: 710280 | G15: Mediterranean California Mesic Mixed Conifer Forest and Woodland | I15: =_xlfn.XLOOKUP(B15,RA_LFBpS_SWO_PAG_PA!B:B,RA_LFBpS_SWO_PAG_PA!C:C) -> White Fir/Dwarf Oregongrape
A16: 3 | B16: ABCO/CACH-CEVE/CAIN9 | C16: White fir - Intermediate | F16: 710280 | G16: Mediterranean California Mesic Mixed Conifer Forest and Woodland | I16: =_xlfn.XLOOKUP(B16,RA_LFBpS_SWO_PAG_PA!B:B,RA_LFBpS_SWO_PAG_PA!C:C) -> #N/A
A17: 5 | B17: ABCO/CEVE-CACH | C17: White fir - Intermediate | F17: 710280 | G17: Mediterranean California Mesic Mixed Conifer Forest and Woodland | I17: =_xlfn.XLOOKUP(B17,RA_LFBpS_SWO_PAG_PA!B:B,RA_LFBpS_SWO_PAG_PA!C:C) -> #N/A
A18: 3 | B18: ABCO/CEVE-CEPR/FRVI | C18: White fir - Cool | F18: 710280 | G18: Mediterranean California Mesic Mixed Conifer Forest and Woodland | I18: =_xlfn.XLOOKUP(B18,RA_LFBpS_SWO_PAG_PA!B:B,RA_LFBpS_SWO_PAG_PA!C:C) -> #N/A
A19: 1 | B19: ABCO/GASH-BENE2 | C19: White fir - Warm moist | F19: 710280 | G19: Mediterranean California Mesic Mixed Conifer Forest and Woodland | I19: =_xlfn.XLOOKUP(B19,RA_LFBpS_SWO_PAG_PA!B:B,RA_LFBpS_SWO_PAG_PA!C:C) -> White Fir-Western Hemlock/Dwarf Oregongrape
A20: 4 | B20: ABCO/QUVA | C20: White fir - Cool | F20: 710280 | G20: Mediterranean California Mesic Mixed Conifer Forest and Woodland | I20: =_xlfn.XLOOKUP(B20,RA_LFBpS_SWO_PAG_PA!B:B,RA_LFBpS_SWO_PAG_PA!C:C) -> White Fir - cool, dry
A21: 5 | B21: ABCO/RHMA3-BENE2 | C21: White fir - Cool | F21: 710280 | G21: Mediterranean California Mesic Mixed Conifer Forest and Woodland | I21: =_xlfn.XLOOKUP(B21,RA_LFBpS_SWO_PAG_PA!B:B,RA_LFBpS_SWO_PAG_PA!C:C) -> White Fir/Pacific Rhododendron
A22: 6 | B22: ABCO/RHMA3-QUSA2 | C22: White fir - Cool | F22: 710280 | G22: Mediterranean California Mesic Mixed Conifer Forest and Woodland | I22: =_xlfn.XLOOKUP(B22,RA_LFBpS_SWO_PAG_PA!B:B,RA_LFBpS_SWO_PAG_PA!C:C) -> White Fir/Pacific Rhododendron
... A135: 2 | B135: PSME/BENE2/POMU | C135: Douglas-fir - Dry | F135: 710270 | G135: Mediterranean California Dry-Mesic Mixed Conifer Forest and Woodland | I135: =_xlfn.XLOOKUP(B135,RA_LFBpS_SWO_PAG_PA!B:B,RA_LFBpS_SWO_PAG_PA!C:C) -> Douglas-fir-Canyon Live Oak-cool, dry - SWO
A136: 3 | B136: PSME/BERE | C136: Douglas-fir - Moist | F136: 710270 | G136: Mediterranean California Dry-Mesic Mixed Conifer Forest and Woodland | I136: Douglas-fir/Creeping Oregon grape
A137: 4 | B137: PSME/COCO6-SYMO/POMU | C137: Douglas-fir - Moist | F137: 710280 | G137: Mediterranean California Mesic Mixed Conifer Forest and Woodland | I137: =_xlfn.XLOOKUP(B137,RA_LFBpS_SWO_PAG_PA!B:B,RA_LFBpS_SWO_PAG_PA!C:C) -> #N/A
A138: 3 | B138: PSME/DRY SHRUB | C138: Douglas-fir - Dry | F138: 710270 | G138: Mediterranean California Dry-Mesic Mixed Conifer Forest and Woodland | I138: =_xlfn.XLOOKUP(B138,RA_LFBpS_SWO_PAG_PA!B:B,RA_LFBpS_SWO_PAG_PA!C:C) -> Douglas-fir/Poison Oak-warm, often low elevation
A139: 5 | B139: PSME/GASH-BENE2 | C139: Douglas-fir - Moist | F139: 710280 | G139: Mediterranean California Mesic Mixed Conifer Forest and Woodland | I139: =_xlfn.XLOOKUP(B139,RA_LFBpS_SWO_PAG_PA!B:B,RA_LFBpS_SWO_PAG_PA!C:C) -> Douglas-fir-Chinquapin/Salal - SWO
A140: 6 | B140: PSME/GASH-RHMA3 | C140: Douglas-fir - Moist | F140: 710280 | G140: Mediterranean California Mesic Mixed Conifer Forest and Woodland | I140: =_xlfn.XLOOKUP(B140,RA_LFBpS_SWO_PAG_PA!B:B,RA_LFBpS_SWO_PAG_PA!C:C) -> Douglas-fir-Chinquapin/Salal - SWO
A141: 4 | B141: PSME/HODI/WHMO-SWO | C141: Douglas-fir - Dry | F141: 710270 | G141: Mediterranean California Dry-Mesic Mixed Conifer Forest and Woodland | I141: =_xlfn.XLOOKUP(B141,RA_LFBpS_SWO_PAG_PA!B:B,RA_LFBpS_SWO_PAG_PA!C:C) -> Douglas-fir/Poison Oak-warm, often low elevation
A142: 5 | B142: PSME/HODI-MANE2 | C142: Douglas-fir - Dry | F142: 710270 | G142: Mediterranean California Dry-Mesic Mixed Conifer Forest and Woodland | I142: Douglas-fir/oceanspray/dwarf Oregon grape
A143: 6 | B143: PSME/HODI-SYMPH | C143: Douglas-fir - Dry | F143: 710270 | G143: Mediterranean California Dry-Mesic Mixed Conifer Forest and Woodland | I143: Douglas-fir/oceanspray-snowberry
A144: 7 | B144: PSME/MANE2 | C144: Douglas-fir - Dry | F144: 710270 | G144: Mediterranean California Dry-Mesic Mixed Conifer Forest and Woodland | I144: Douglas-fir/dwarf Oregon grape
A145: 7 | B145: PSME/MANE2-GASH | C145: Douglas-fir - Moist | F145: 710280 | G145: Mediterranean California Mesic Mixed Conifer Forest and Woodland | I145: =_xlfn.XLOOKUP(B145,RA_LFBpS_SWO_PAG_PA!B:B,RA_LFBpS_SWO_PAG_PA!C:C) -> #N/A
A146: 10 | B146: PSME/QUVA | C146: Ultramafic, cold | F146: 710270 | G146: Mediterranean California Dry-Mesic Mixed Conifer Forest and Woodland | I146: =_xlfn.XLOOKUP(B146,RA_LFBpS_SWO_PAG_PA!B:B,RA_LFBpS_SWO_PAG_PA!C:C) -> Douglas-fir-Ultramafic - SWO
A147: 11 | B147: PSME/QUVA-ARNE/XETE | C147: Ultramafic, cold | F147: 710280 | G147: Mediterranean California Mesic Mixed Conifer Forest and Woodland | I147: =_xlfn.XLOOKUP(B147,RA_LFBpS_SWO_PAG_PA!B:B,RA_LFBpS_SWO_PAG_PA!C:C) -> Douglas-fir-Ultramafic - SWO
A148: 8 | B148: PSME/QUVA-RHMA3 | C148: Douglas-fir - Dry | F148: 710270 | G148: Mediterranean California Dry-Mesic Mixed Conifer Forest and Woodland | I148: Douglas-fir/huckleberry oak-rhodedendron
A149: 8 | B149: PSME/RHMA3-VAOV2 | C149: Douglas-fir - Moist | F149: 710280 | G149: Mediterranean California Mesic Mixed Conifer Forest and Woodland | I149: =_xlfn.XLOOKUP(B149,RA_LFBpS_SWO_PAG_PA!B:B,RA_LFBpS_SWO_PAG_PA!C:C) -> #N/A
A150: 9 | B150: PSME/TODI | C150: Douglas-fir - Dry | F150: 710270 | G150: Mediterranean California Dry-Mesic Mixed Conifer Forest and Woodland | I150: Douglas-fir/poison oak
A151: 25 | B151: PSME-ABCO | C151: White fir - Intermediate | F151: 710270 | G151: Mediterranean California Dry-Mesic Mixed Conifer Forest and Woodland | I151: =_xlfn.XLOOKUP(B151,RA_LFBpS_SWO_PAG_PA!B:B,RA_LFBpS_SWO_PAG_PA!C:C) -> White Fir-Douglas-fir - warm, dry
A152: 9 | B152: PSME-ABCO/HODI | C152: Douglas-fir - Moist | F152: 710280 | G152: Mediterranean California Mesic Mixed Conifer Forest and Woodland | I152: =_xlfn.XLOOKUP(B152,RA_LFBpS_SWO_PAG_PA!B:B,RA_LFBpS_SWO_PAG_PA!C:C) -> #N/A
...

Sheet SWOR_PA_PVT_SDI
A1: PlantAssociations | B1: Series | C1: PVT | D1: SDImax | E1: Climate adaptive density target species | F1: Number of plots | G1: Comment
A2: PSME/ACCI-BENE2 | B2: =LEFT(A2,4) -> PSME | C2: Douglas-fir - Dry | D2: 561 | E2: PILA | G2: Yes, but possibly PSME if Organon Max SDI's are lower than PILAs
A3: PSME/ARNE-SWO | B3: =LEFT(A3,4) -> PSME | C3: Douglas-fir - Dry | D3: 561 | E3: PILA | F3: 14 | G3: Yes, but possibly PSME if Organon Max SDI's are lower than PILAs
A4: PSME/BENE2/POMU | B4: =LEFT(A4,4) -> PSME | C4: Douglas-fir - Dry | D4: 576 | E4: CADE27 | F4: 11 | G4: Yes
A5: PSME/DRY SHRUB | B5: =LEFT(A5,4) -> PSME | C5: Douglas-fir - Dry | D5: 530 | E5: PSME | F5: 423 | G5: Yes, ORGANON
A6: PSME/HODI/WHMO-SWO | B6: =LEFT(A6,4) -> PSME | C6: Douglas-fir - Dry | D6: 530 | E6: PSME | F6: 122 | G6: Yes, ORGANON
A7: PSME/HODI-MANE2 | B7: =LEFT(A7,4) -> PSME | C7: Douglas-fir - Dry | D7: 365 | E7: PIPO | G7: Yes, ICASCA
A8: PSME-CADE27 | B8: =LEFT(A8,4) -> PSME | C8: Douglas-fir - Dry | D8: 264 | E8: PIJE | G8: Yes, weighted ecoplot
A9: PSME-CADE27/BEPI2 | B9: =LEFT(A9,4) -> PSME | C9: Douglas-fir - Dry | D9: 365 | E9: PIPO | G9: Yes, ICASCA
A10: PSME-PIPO/RHDI6 | B10: =LEFT(A10,4) -> PSME | C10: Douglas-fir - Dry | D10: 365 | E10: PIPO | F10: 84 | G10: Yes, ICASCA
A11: PSME-QUCH2/BENE2 | B11: =LEFT(A11,4) -> PSME | C11: Douglas-fir - Dry | D11: 530 | E11: PSME | F11: 131 | G11: Yes, ORGANON
A12: PSME-QUCH2/RHDI6 | B12: =LEFT(A12,4) -> PSME | C12: Douglas-fir - Dry | D12: 530 | E12: PSME | F12: 171 | G12: Yes, ORGANON
A13: PSME-QUCH2-LIDE3 | B13: =LEFT(A13,4) -> PSME | C13: Douglas-fir - Dry | D13: 365 | E13: PIPO | F13: 41 | G13: Yes, ICASCA
A14: PSME-QUKE/RHDI6 | B14: =LEFT(A14,4) -> PSME | C14: Douglas-fir - Dry | D14: 365 | E14: PIPO | F14: 17 | G14: Yes, ICASCA
A15: PSME/GASH-BENE2 | B15: =LEFT(A15,4) -> PSME | C15: Douglas-fir - Moist | D15: 530 | E15: PSME | F15: 3 | G15: Yes, ORGANON
A16: PSME/GASH-RHMA3 | B16: =LEFT(A16,4) -> PSME | C16: Douglas-fir - Moist | D16: 561 | E16: PILA | G16: Yes, but possibly PSME if Organon Max SDI's are lower than PILAs
A17: PSME/RUSP/POMU | B17: =LEFT(A17,4) -> PSME | C17: Douglas-fir - Moist | D17: 530 | E17: PSME | G17: Yes, ORGANON
A18: PSME-CACH6/BENE2 | B18: =LEFT(A18,4) -> PSME | C18: Douglas-fir - Moist | D18: 561 | E18: PILA | G18: Yes, but possibly PSME if Organon Max SDI's are lower than PILAs
A19: PIJE/CECU/FEID | B19: =LEFT(A19,4) -> PIJE | C19: Jeffrey pine | D19: 264 | E19: PIJE | G19: Yes, weighted ecoplot
A20: PIJE/FEID | B20: =LEFT(A20,4) -> PIJE | C20: Jeffrey pine | D20: 264 | E20: PIJE | G20: Yes, weighted ecoplot
A21: PIJE/QUVA-ARNE | B21: =LEFT(A21,4) -> PIJE | C21: Jeffrey pine | D21: 264 | E21: PIJE | G21: Yes, weighted ecoplot
A22: PIJE/QUVA-ARNE-GABU2 | B22: =LEFT(A22,4) -> PIJE | C22: Jeffrey pine | D22: 264 | E22: PIJE | G22: Yes, weighted ecoplot
A23: PIJE-CADE27/ARVI4 | B23: =LEFT(A23,4) -> PIJE | C23: Jeffrey pine | D23: 264 | E23: PIJE | G23: Yes, weighted ecoplot
A24: PIJE-CADE27/QUVA | B24: =LEFT(A24,4) -> PIJE | C24: Jeffrey pine | D24: 264 | E24: PIJE | G24: Yes, weighted ecoplot
A25: PIJE-CADE27-PSME | B25: =LEFT(A25,4) -> PIJE | C25: Jeffrey pine | D25: 264 | E25: PIJE | G25: Yes, weighted ecoplot
A26: PIMO3-PIJE/QUVA/XETE | B26: =LEFT(A26,5) -> PIMO3 | C26: Jeffrey pine | D26: 264 | E26: PIJE | G26: Yes, weighted ecoplot
A27: PSME-CADE27-PIJE | B27: =LEFT(A27,4) -> PSME | C27: Jeffrey pine | D27: 264 | E27: PIJE | G27: Yes, weighted ecoplot
A28: PICO/VAME-VASC | B28: =LEFT(A28,4) -> PICO | C28: Lodgepole pine - Cold | D28: 541 | E28: PICO-R6 | G28: SCORNECA Max SDI, Cascadian distribution
A29: PICO-ABCO-PSME | B29: =LEFT(A29,4) -> PICO | C29: Lodgepole pine - Cold | D29: 447 | E29: PIMO3 - R6Max | G29: SCORNECA Max SDI, Cascadian distribution
A30: PICO-TSME/DEP | B30: =LEFT(A30,4) -> PICO | C30: Lodgepole pine - Cold | D30: 541 | E30: PICO-R6 | G30: SCORNECA Max SDI, Cascadian distribution
A31: ABMAS-TSME/ARNE/CHUM | B31: =LEFT(A31,5) -> ABMAS | C31: Mountain hemlock - Cold dry | D31: 447 | E31: PIMO3 - R6Max | G31: SCORNECA Max SDI, Cascadian distribution
A32: TSME/ARNE/CHUM | B32: =LEFT(A32,4) -> TSME | C32: Mountain hemlock - Cold dry | D32: 447 | E32: PIMO3 - R6Max | G32: SCORNECA Max SDI, Cascadian distribution
A33: TSME/HERB | B33: =LEFT(A33,4) -> TSME | C33: Mountain hemlock - Cold dry | D33: 450 | E33: ABMAS - R6 | G33: SCORNECA Max SDI, Cascadian distribution
A34: TSME/RHMA3/XETE | B34: =LEFT(A34,4) -> TSME | C34: Mountain hemlock - Cold dry | D34: 447 | E34: PIMO3 - R6Max | G34: SCORNECA Max SDI, Cascadian distribution
A35: TSME/VAME/PYSE | B35: =LEFT(A35,4) -> TSME | C35: Mountain hemlock - Cold dry | D35: 447 | E35: PIMO3 - R6Max | G35: SCORNECA Max SDI, Cascadian distribution
A36: TSME/VASC/CHUM | B36: =LEFT(A36,4) -> TSME | C36: Mountain hemlock - Cold dry | D36: 450 | E36: ABMAS - R6 | G36: SCORNECA Max SDI, Cascadian distribution
A37: TSME-ABMAS/RULA2/PYSE | B37: =LEFT(A37,4) -> TSME | C37: Mountain hemlock - Cold dry | D37: 450 | E37: ABMAS - R6 | G37: SCORNECA Max SDI, Cascadian distribution
A38: TSME-ABMAS/VAME/CHUM | B38: =LEFT(A38,4) -> TSME | C38: Mountain hemlock - Cold dry | D38: 447 | E38: PIMO3 - R6Max | G38: SCORNECA Max SDI, Cascadian distribution
A39: QUGA4/CYEC | B39: =LEFT(A39,4) -> QUGA | C39: Oregon white oak | D39: 200 | E39: QUGA | F39: 139 | G39: Yes, SCORNECA FVS, ICASCA 440!
A40: QUGA4-PSME/RHDI6 | B40: =LEFT(A40,4) -> QUGA | C40: Oregon white oak | D40: 200 | E40: QUGA | F40: 48 | G40: Yes, SCORNECA FVS, ICASCA 440!
...

Sheet PivotTableSeries
A1: Comment | B1: (Multiple Items)
A3: Count of PlantAssociations | B3: Adaptive tree species/early seral
A4: Series | B4: ABMAS | C4: CADE27 | D4: PICO | E4: PIJE | F4: PILA | G4: PIMO3 | H4: PIPO | I4: PSME | J4: QUGA | K4: (blank) | L4: Grand Total
A5: ABAM | G5: 1 | I5: 1 | L5: 2
A6: ABCO | C6: 1 | F6: 7 | H6: 2 | I6: 10 | L6: 20
A7: CHLA | F7: 2 | G7: 1 | I7: 5 | L7: 8
A8: LIDE | E8: 1 | F8: 4 | G8: 2 | I8: 9 | L8: 16
A9: PICO | D9: 2 | G9: 1 | L9: 3
A10: PIJE | E10: 7 | L10: 7
A11: PIPO | H11: 2 | L11: 2
A12: PSME | C12: 1 | E12: 3 | F12: 4 | H12: 6 | I12: 8 | L12: 22
A13: QUGA | J13: 2 | L13: 2
A14: THPL | I14: 1 | L14: 1
A15: TSHE | B15: 1 | F15: 3 | G15: 1 | I15: 15 | L15: 20
A16: TSME | B16: 3 | G16: 4 | L16: 7
A17: (blank)
A18: ABMAS | B18: 2 | C18: 1 | G18: 4 | I18: 2 | L18: 9
A19: PIMO3 | E19: 1 | G19: 2 | L19: 3
A20: Grand Total | B20: 6 | C20: 3 | D20: 2 | E20: 12 | F20: 20 | G20: 16 | H20: 10 | I20: 51 | J20: 2 | L20: 122

Sheet Sheet1
A1: Count of PlantAssociations | B1: Adaptive tree species/early seral
A2: Series | B2: ABMAS | C2: CADE27 | D2: PICO | E2: PIJE | F2: PILA | G2: PIMO3 | H2: PIPO | I2: PSME | J2: QUGA | K2: Grand Total
A3: ABAM | G3: 1 | I3: 1 | K3: 2
A4: ABCO | C4: 1 | F4: 7 | H4: 2 | I4: 10 | K4: 20
A5: ABMAS | B5: 2 | C5: 1 | G5: 4 | I5: 2 | K5: 9
A6: CHLA | F6: 2 | G6: 1 | I6: 5 | K6: 8
A7: LIDE | E7: 1 | F7: 4 | G7: 2 | I7: 9 | K7: 16
A8: PICO | D8: 2 | G8: 1 | K8: 3
A9: PIJE | E9: 7 | K9: 7
A10: PIMO3 | E10: 1 | G10: 2 | K10: 3
A11: PIPO | H11: 2 | K11: 2
A12: PSME | C12: 1 | E12: 3 | F12: 4 | H12: 6 | I12: 8 | K12: 22
A13: QUGA | J13: 2 | K13: 2
A14: THPL | I14: 1 | K14: 1
A15: TSHE | B15: 1 | F15: 3 | G15: 1 | I15: 15 | K15: 20
A16: TSME | B16: 3 | G16: 4 | K16: 7
A17: Grand Total | B17: 6 | C17: 3 | D17: 2 | E17: 12 | F17: 20 | G17: 16 | H17: 10 | I17: 51 | J17: 2 | K17: 122

Sheet References_CSE
A1: Plot Num | B1: PlantSeries | C1: Field-PlantAssociation | D1: Common Name | E1: Potential Vegetation Type
A2: 8 | B2: ABCO | C2: ABCO/BENE2 | E2: White fir - Intermediate
A3: 1 | B3: ABCO | C3: ABCO/BENE2/ACTR | E3: White fir - Intermediate
A4: 3 | B4: ABCO | C4: ABCO/BENE2/LIBOL | E4: White fir - Intermediate
A5: 35 | B5: ABCO | C5: ABCO/MANE2 | D5: white fir/Cascade barberry | E5: White fir - Intermediate
A6: 1 | B6: ABCO | C6: ABCO/MANE2/LIBOL2 | D6: white fir/Cascade barberry/longtube twinflower | E6: White fir - Intermediate
A7: 10 | B7: ABCO | C7: ABCO/SYMO | D7: white fir/creeping snowberry | E7: White fir - Intermediate
A8: 5 | B8: ABCO | C8: ABCO-ABMAS/CHUM-ANDE3 | E8: White fir - Cool
A9: 1 | B9: ABCO | C9: ABCO-CADE27/TRBOL | D9: white fir-incense cedar/broadleaf starflower | E9: White fir - Intermediate
A10: 1 | B10: ABCO | C10: ABCO-LIDE3/CHUM | E10: White fir - Cool
A11: 36 | B11: ABCO | C11: ABCO-PSME/ROGY | D11: white fir-Douglas-fir/dwarf rose | E11: White fir - Intermediate
A12: 3 | B12: LIDE | C12: LIDE3-PSME-QUCH2/RHDI6 | E12: Tanoak - Douglas-fir - Dry
A13: 3 | B13: LIDE | C13: LIDE3-PSME-QUCHE2/BENE2 | E13: Tan oak - Douglas-fir - Dry
A14: 17 | B14: PIPO | C14: PIPO-PSME | D14: ponderosa pine-Douglas-fir | E14: Ponderosa pine - Dry
A15: 26 | B15: PSME | C15: PSME/2SHRUB | D15: Douglas-fir/dry shrub | E15: Douglas-fir - Dry
A16: 2 | B16: PSME | C16: PSME/ARNE | D16: Douglas-fir/pinemat manzanita (southwest Oregon) | E16: Douglas-fir - Dry
A17: 2 | B17: PSME | C17: PSME/ARNE-SWO | E17: Douglas-fir - Dry
A18: 1 | B18: PSME | C18: PSME/BENE2/POMU | E18: Douglas-fir - Moist
A19: 4 | B19: PSME | C19: PSME/MANE2/POMU | D19: Douglas-fir/Cascade barberry/western swordfern
A20: 10 | B20: PSME | C20: PSME/DRY SHRUB | E20: Douglas-fir - Dry
A21: 4 | B21: PSME | C21: PSME/HODI/WHMO | D21: Douglas-fir/oceanspray/common whipplea
A22: 8 | B22: PSME | C22: PSME/HODI/WHMO-SWO | E22: Douglas-fir - Dry
A23: 3 | B23: PSME | C23: PSME/QUVA-ARNE/XETE | D23: Douglas-fir/huckleberry oak-pinemat manzanita/common beargrass
A24: 46 | B24: PSME | C24: PSME-ABCO | D24: Douglas-fir-white fir | E24: White fir - Intermediate
A25: 40 | B25: PSME | C25: PSME-ABCO/SYMO | D25: Douglas-fir-white fir/creeping snowberry | E25: White fir - Intermediate
A26: 8 | B26: PSME | C26: PSME-CADE27/BEPI2 | E26: Douglas-fir - Dry
A27: 448 | B27: PSME | C27: PSME-CADE27/MAAQ2 | D27: Douglas-fir-incense cedar/hollyleaved barberry
A28: 2 | B28: PSME | C28: PSME-CADE27-PIJE | E28: Jeffrey pine
A29: 30 | B29: PSME | C29: PSME-PIPO/RHDI6 | E29: Douglas-fir - Dry
A30: 44 | B30: PSME | C30: PSME-PIPO/TODI | D30: Douglas-fir-ponderosa pine/Pacific poison oak | E30: Douglas-fir - Dry
A31: 7 | B31: PSME | C31: PSME-QUCH2/RHDI6 | E31: Douglas-fir - Dry

Sheet MaxSDIAnalysis
A1: Potential Vegetation Type | B1: Dry/Moist | C1: Early Seral | D1: Max SDI For Analysis | E1: MaxSDI Source | F1: FVS_SDI MAX Variant Specific | G1: Ecology Group data | H1: Tempered SDI Max Value | I1: Comments
A2: Douglas-fir - Dry | B2: Dry | C2: Ponderosa | D2: 499 | E2: Organon | F2: 720 | G2: 634 | H2: 640
A3: Douglas-fir - Moist | B3: Moist | C3: Ponderosa | D3: 499 | E3: Organon | F3: 765 | G3: 708 | H3: 760
A4: Jeffrey pine | B4: Dry | C4: Jeffrey | D4: 264 | E4: EcoPlots Weighted Max SDI Ultramafic | F4: 360 | G4: 212 | H4: 285
A5: Lodgepole pine - Dry | B5: Dry | C5: Lodgepole | D5: 400 | E5: FVS R6 S Central OR NE CA | G5: 300 | H5: 340
A6: Lodgepole pine cold | B6: Moist | C6: Lodgepole | D6: 400 | E6: FVS R6 S Central OR NE CA | G6: 300 | H6: 340
A7: Mixed Conifer - Cold/dry | B7: Dry | C7: Douglas-fir | D7: 530 | E7: Organon
A8: Mixed Conifer - Dry | B8: Dry | C8: Ponderosa | D8: 499 | E8: Organon
A9: Mixed Conifer - Moist | B9: Moist | C9: Douglas-fir | D9: 547 | E9: FVS R6 S Central OR NE CA
A10: Mountain hemlock - Cold/Dry | B10: Moist | C10: Shasta red | D10: 755 | E10: FVS ICASCA R6 plant association | F10: 740 | G10: 725 | H10: 745
A11: Mountain hemlock - Cold/Dry (Coastal/W.Cascades) | B11: Moist | C11: Shasta red | D11: 755 | E11: FVS ICASCA R6 plant association | F11: 740 | G11: 725 | H11: 745
A12: Mountain hemlock - Intermediate | B12: Moist | C12: Shasta red | D12: 755 | E12: FVS ICASCA R6 plant association | F12: 740 | G12: 725 | H12: 745
A13: Oregon white oak | B13: Dry | C13: White oak | D13: 200 | E13: FVS R6 S Central OR NE CA
A14: Oregon white oak - Ponderosa pine | B14: Dry | C14: White oak | D14: 200 | E14: FVS R6 S Central OR NE CA
A15: Pacific silver fir - Intermediate | B15: Moist | C15: Shasta red | D15: 755 | E15: FVS ICASCA R6 plant association | F15: 760 | G15: 760 | H15: 760
A16: Pacific silver fir - Warm | B16: Moist | C16: Douglas-fir | D16: 755 | E16: FVS ICASCA R6 plant association | F16: 955 | G16: 1010 | H16: 900
A17: Ponderosa pine - Dry | B17: Dry | C17: Ponderosa | D17: 499 | E17: Organon
A18: Ponderosa pine - Dry, with juniper | B18: Dry | C18: Ponderosa | D18: 499 | E18: Organon
A19: Ponderosa pine - Lodgepole pine | B19: Dry | C19: Ponderosa | D19: 499 | E19: Organon
A20: Shasta red fir - Dry | B20: Moist | C20: Shasta red | D20: 755 | E20: FVS ICASCA R6 plant association | F20: 675 | H20: 700
A21: Shasta red fir - Moist | B21: Moist | C21: Shasta red | D21: 755 | E21: FVS ICASCA R6 plant association | F21: 715 | G21: 685 | H21: 700
A22: Sitka spruce | B22: Moist | C22: Sitka spruce | D22: 700 | E22: FVS Pacific Northwest Coastal Variant
A23: Tan oak - Douglas-fir - Dry | B23: Dry | C23: Douglas-fir | D23: 600 | E23: ICASCA Variant FVS | F23: 915 | G23: 850 | H23: 820
A24: Tan oak - Douglas-fir - Moist | B24: Moist | C24: Douglas-fir | D24: 600 | E24: ICASCA Variant FVS | F24: 650 | G24: 1050 | H24: 860
A25: Ultramafic | B25: Dry | C25: Jeffrey | D25: 294 | E25: EcoPlots Weighted Max SDI Ultramafic | G25: 218 | H25: 285
A26: Western hemlock - Hyperdry | B26: Moist | C26: Douglas-fir | D26: 600 | E26: ICASCA Variant FVS | G26: 765 | H26: 800
A27: Western hemlock - Intermediate | B27: Moist | C27: Douglas-fir | D27: 600 | E27: ICASCA Variant FVS | G27: 720 | H27: 800
A28: Western hemlock - Moist | B28: Moist | C28: Douglas-fir | D28: 600 | E28: ICASCA Variant FVS | G28: 640 | H28: 690
A29: White fir - Cool | B29: Moist | C29: Shasta red | D29: 750 | E29: FVS R6 S Central OR NE CA
A30: White fir - Intermediate | B30: Dry | C30: Douglas-fir | D30: 530 | E30: Organon | F30: 1340 | G30: 825
A31: White fir - Moist | B31: Moist | C31: Shasta red | D31: 750 | E31: FVS R6 S Central OR NE CA | F31: 900 | G31: 920 | H31: 700

Sheet MaxSDISource
A1: Code | B1: PA_Code | C1: Common | D1: Needed for Analysis | E1: Climate Adaptive Max SDI | F1: ORGANON MAXSDI | G1: FVS ICASCA R5 Max SDI | H1: FVS R6 Central OR NA CA | I1: FVS West Cascades | J1: FVS_SCOR_NECA | K1: Bybee EA | L1: FVS_KlamathVariant
A2: ABCO | B2: ABCO | C2: white fir | D2: 0 | E2: =MIN(F2:L2) -> 659 | F2: 752 | G2: 800 | J2: 659 | L2: 800
A3: ABMAS | B3: ABMAS | C3: Shasta red fir | D3: 1 | E3: =MIN(F3:L3) -> 450 | G3: 1000 | J3: 450 | L3: 1000
A4: ABPR | B4: ABPR | C4: noble fir | D4: 1 | E4: =MIN(F4:L4) -> 659 | J4: 659
A5: ACMA | B5: ACMA | C5: bigleaf maple | D5: 0 | E5: =MIN(F5:L5) -> 300 | G5: 629 | J5: 300
A6: ARME | B6: ARME | C6: Pacific madrone | D6: 0 | E6: =MIN(F6:L6) -> 515 | G6: 515 | L6: 515
A7: CADE | B7: CADE27 | C7: incense-cedar | D7: 1 | E7: =MIN(F7:L7) -> 447 | G7: 576 | J7: 447 | L7: 576
A8: CHCH | B8: CHCH | C8: giant chinquapin | D8: 0 | E8: =MIN(F8:L8) -> 250 | G8: 785 | J8: 250
A9: CHLA | B9: CHLA | C9: Port-Orford cedar | D9: 0 | E9: =MIN(F9:L9) -> 592 | G9: 592
A10: CONU | B10: CONU | C10: Pacific dogwood | D10: 0 | E10: =MIN(F10:L10) -> 406 | G10: 406
A11: FRLA | B11: FRLA | C11: Oregon ash | D11: 0 | E11: =MIN(F11:L11) -> 550 | G11: 550
A12: NODE | B12: LIDE2 | C12: tanoak | D12: 0 | E12: =MIN(F12:L12) -> 785 | G12: 785 | L12: 785
A13: PIAT | B13: PIAT | C13: knobcone pine | D13: 0 | E13: =MIN(F13:L13) -> 679 | G13: 679
A14: PICO | B14: PICO | C14: lodgepole | D14: 0 | E14: =MIN(F14:L14) -> 400 | G14: 679 | H14: 400 | J14: 541
A15: PILA | B15: PILA | C15: sugar pine | D15: 1 | E15: =MIN(F15:L15) -> 447 | G15: 561 | J15: 447 | L15: 561
A16: PIJE | B16: PIJE | C16: jeffrey pine | D16: 1 | E16: =MIN(F16:L16) -> 365 | G16: 365
A17: PIMO | B17: PIMO3 | C17: Western white pine | D17: 1 | E17: =MIN(F17:L17) -> 272 | G17: 272 | J17: 447
A18: PIPO | B18: PIPO | C18: ponderosa pine | D18: 1 | E18: =MIN(F18:L18) -> 365 | F18: 499 | G18: 365 | J18: 429 | K18: 430 | L18: 365
A19: PISI | B19: PISI | C19: Sitka spruce | D19: 0 | E19: =MIN(F19:L19) -> 619 | J19: 619
A20: PSME | B20: PSME | C20: Douglas-fir | D20: 1 | E20: =MIN(F20:L20) -> 530 | F20: 530 | G20: 570 | H20: 547 | J20: 767 | K20: 664 | L20: 570
A21: QUCH | B21: QUCH | C21: canyon live oak | D21: 0 | E21: =MIN(F21:L21) -> 667 | G21: 667
A22: QUGA | B22: QUGA | C22: Oregon white oak | D22: 1 | E22: =MIN(F22:L22) -> 200 | G22: 440 | H22: 200 | J22: 200
A23: QUKE | B23: QUKE | C23: California black oak | D23: 0 | E23: =MIN(F23:L23) -> 406 | G23: 550 | L23: 406
A24: SESE | B24: SESE | C24: redwood | D24: 0 | E24: =MIN(F24:L24) -> 1052 | G24: 1052 | L24: 1052
A25: TABR | B25: TABR | C25: Pacific yew | D25: 0 | E25: =MIN(F25:L25) -> 570 | G25: 570
A26: THPL | B26: THPL | C26: western red cedar | D26: 0 | E26: =MIN(F26:L26) -> 650 | G26: 762 | J26: 650
A27: TSHE | B27: TSHE | C27: western hemlock | D27: 0 | E27: =MIN(F27:L27) -> 650 | G27: 682 | J27: 650
A28: TSME | B28: TSME | C28: mountain hemlock | D28: 0 | E28: =MIN(F28:L28) -> 687 | G28: 687 | J28: 758
A29: Z_Comment | F29: Hann & Wang 1990 for above. Plots from High Cascades and north of Grants Pass, past Glendale. The SDI maximum for all species is assigned from the SDI maximum associated with the site species for the plant association code shown in Appendix A. SDI maximums were set based on growth basal area (GBA) analysis developed by Hall (1983) or an analysis of Current Vegetation Survey (CVS) plots in USFS Region 6 by Crookston (2008). Some SDI maximums associated with plant associations are unreasonably large, so SDI maximums are capped at 950. Maximum stand density index at the stand level is a weighted average, by basal area, of the individual species SDI maximums. | G29: Sets Extremely high Max SDI by plant association, or Table 3.5.1 from FIA, John Shaw | I29: If a user specified basal area maximum is present, the maximum SDI for all species is computed using equation {3.5.1}; otherwise, the SDI maximum for all species is assigned from the SDI maximum associated with the site species for the plant association code shown in Appendix B. - Very high, set by plant association | J29: R6 & Warm Springs | L29: Sets Extremely high Max SDI by plant association, or Table 3.5.1 from FIA, John Shaw

Sheet References Data
A1: CountOfPCID | B1: PlantSeries | C1: Field-PlantAssociation | D1: Common Name | E1: Potential Vegetation Type
A2: 8 | B2: ABCO | C2: ABCO/BENE2 | E2: White fir - Intermediate
A3: 1 | B3: ABCO | C3: ABCO/BENE2/ACTR | E3: White fir - Intermediate
A4: 3 | B4: ABCO | C4: ABCO/BENE2/LIBOL | E4: White fir - Intermediate
A5: 1 | B5: ABCO | C5: ABCO/SYMO | E5: White fir - Intermediate
A6: 5 | B6: ABCO | C6: ABCO-ABMAS/CHUM-ANDE3 | E6: White fir - Cool
A7: 1 | B7: ABCO | C7: ABCO-LIDE3/CHUM | E7: White fir - Cool
A8: 2 | B8: ABCO | C8: ABCO-PSME/ROGY | E8: White fir - Intermediate
A9: 3 | B9: LIDE | C9: LIDE3-PSME-QUCH2/RHDI6 | E9: Tanoak - Douglas-fir - Dry
A10: 3 | B10: LIDE | C10: LIDE3-PSME-QUCHE2/BENE2 | E10: Tan oak - Douglas-fir - Dry
A11: 5 | B11: PIPO | C11: PIPO-PSME | E11: Ponderosa pine - Dry
A12: 2 | B12: PSME | C12: PSME/ARNE-SWO | E12: Douglas-fir - Dry
A13: 1 | B13: PSME | C13: PSME/BENE2/POMU | E13: Douglas-fir - Moist
... A21: 7 | B21: PSME | C21: PSME-QUCH2/RHDI6 | E21: Douglas-fir - Dry
A23: CountOfSTANDPLOT_ID | B23: Primary_Se | C23: Scientific | D23: CommonName
A24: 35 | B24: ABCO | C24: ABCO/MANE2 | D24: white fir/Cascade barberry
A26: 1 | B26: ABCO | C26: ABCO/MANE2/LIBOL2 | D26: white fir/Cascade barberry/longtube twinflower
A27: 9 | B27: ABCO | C27: ABCO/SYMO | D27: white fir/creeping snowberry
A28: 1 | B28: ABCO | C28: ABCO-CADE27/TRBOL | D28: white fir-incense cedar/broadleaf starflower
A29: 34 | B29: ABCO | C29: ABCO-PSME/ROGY | D29: white fir-Douglas-fir/dwarf rose
A30: 12 | B30: PIPO | C30: PIPO-PSME | D30: ponderosa pine-Douglas-fir
A31: 26 | B31: PSME | C31: PSME/2SHRUB | D31: Douglas-fir/dry shrub
A32: 2 | B32: PSME | C32: PSME/ARNE | D32: Douglas-fir/pinemat manzanita (southwest Oregon)
A33: 4 | B33: PSME | C33: PSME/HODI/WHMO | D33: Douglas-fir/oceanspray/common whipplea
A34: 4 | B34: PSME | C34: PSME/MANE2/POMU | D34: Douglas-fir/Cascade barberry/western swordfern
A35: 3 | B35: PSME | C35: PSME/QUVA-ARNE/XETE | D35: Douglas-fir/huckleberry oak-pinemat manzanita/common beargrass
A36: 36 | B36: PSME | C36: PSME-ABCO | D36: Douglas-fir-white fir
... A39: 44 | B39: PSME | C39: PSME-PIPO/TODI | D39: Douglas-fir-ponderosa pine/Pacific poison oak

Sheet Ashland_CSE
A1: CountOfSTANDPLOT_ID | B1: Primary_Se | C1: Scientific | D1: CommonName
A2: 35 | B2: ABCO | C2: ABCO/MANE2 | D2: white fir/Cascade barberry
A3: 1 | B3: ABCO | C3: ABCO/MANE2/LIBOL2 | D3: white fir/Cascade barberry/longtube twinflower
A4: 9 | B4: ABCO | C4: ABCO/SYMO | D4: white fir/creeping snowberry
A5: 1 | B5: ABCO | C5: ABCO-CADE27/TRBOL | D5: white fir-incense cedar/broadleaf starflower
A6: 34 | B6: ABCO | C6: ABCO-PSME/ROGY | D6: white fir-Douglas-fir/dwarf rose
A7: 12 | B7: PIPO | C7: PIPO-PSME | D7: ponderosa pine-Douglas-fir
A8: 26 | B8: PSME | C8: PSME/2SHRUB | D8: Douglas-fir/dry shrub
A9: 2 | B9: PSME | C9: PSME/ARNE | D9: Douglas-fir/pinemat manzanita (southwest Oregon)
A10: 4 | B10: PSME | C10: PSME/HODI/WHMO | D10: Douglas-fir/oceanspray/common whipplea
A11: 4 | B11: PSME | C11: PSME/MANE2/POMU | D11: Douglas-fir/Cascade barberry/western swordfern
A12: 3 | B12: PSME | C12: PSME/QUVA-ARNE/XETE | D12: Douglas-fir/huckleberry oak-pinemat manzanita/common beargrass
A13: 36 | B13: PSME | C13: PSME-ABCO | D13: Douglas-fir-white fir
... A16: 44 | B16: PSME | C16: PSME-PIPO/TODI | D16: Douglas-fir-ponderosa pine/Pacific poison oak

Sheet RA_LFBpS_SWO_PAG_PA
A1: SWOPAG | B1: Blue Book Plant Association | C1: P/A Blue Book PAG Name | D1: RA# BpS | E1: NATL BpS | F1: VDDT | G1: VDDT Name (Group for DecAID Crosswalk)
A2: 2206 | B2: ABAM/ROGY/ACTR | C2: Pacific Silver Fir/Vanillaleaf-Coolwort Foamflower - mesic | D2: ABAMlw | E2: 711740 | F2: N514si | G2: Pacific silver fir - intermediate
A3: 2206 | B3: ABAM-TSHE/VAME/ACTR | C3: Pacific Silver Fir/Vanillaleaf-Coolwort Foamflower - mesic | D3: ABAMlw | E3: 711740 | F3: N514si | G3: Pacific silver fir - intermediate
A4: 2204 | B4: ABAM-TSME/VAME/ACTR | C4: Pacific Silver Fir/Big Huckleberry/Beargrass | D4: ABAMup | E4: 711740 | F4: N514si | G4: Pacific silver fir - intermediate
A5: 2002 | B5: ABCO/ACCI/OXOR | C5: White Fir/Pacific Rhododendron | D5: MCONsw | E5: 710280 | F5: S413cw | G5: White fir cool
A6: 2001 | B6: ABCO/ARNE | C6: White Fir - cool, dry | D6: MCONsw | E6: 710280 | F6: S413cw | G6: White fir cool
A7: 2003 | B7: ABCO/BENE2 | C7: White Fir/Dwarf Oregongrape | D7: MCONsw | E7: 710280 | F7: S415iw | G7: White fir intermediate
A8: 2003 | B8: ABCO/BENE2/ACTR | C8: White Fir/Dwarf Oregongrape | D8: MCONsw | E8: 710280 | F8: S415iw | G8: White fir intermediate
A9: 2003 | B9: ABCO/BENE2/LIBOL | C9: White Fir/Dwarf Oregongrape | D9: MCONsw | E9: 710280 | F9: S415iw | G9: White fir intermediate
A10: 2006 | B10: ABCO/GASH-BENE2 | C10: White Fir-Western Hemlock/Dwarf Oregongrape | D10: MCONsw | E10: 710280 | F10: S414vw | G10: White fir warm-moist
A11: 2001 | B11: ABCO/QUVA | C11: White Fir - cool, dry | D11: MCONsw | E11: 710280 | F11: S413cw | G11: White fir cool
A12: 2002 | B12: ABCO/RHMA3-BENE2 | C12: White Fir/Pacific Rhododendron | D12: MCONsw | E12: 710280 | F12: S413cw | G12: White fir cool
A13: 2002 | B13: ABCO/RHMA3-QUSA2 | C13: White Fir/Pacific Rhododendron | D13: MCONsw | E13: 710280 | F13: S413cw | G13: White fir cool
... A40: 1303 | B40: CHLA-TSHE/POMU | C40: Port-Orford Cedar/Western Swordfern | D40: DFHEwt | E40: 210390 | F40: S405hc | G40: Western hemlock moist (Cascades)
A41: 1521 | B41: LIDE3/ARCTO3/XETE | C41: Tanoak-Ultramafic | D41: MEVG | E41: 0710430/Interior/10431 | F41: S408td | G41: Tan oak/Douglas-fir dry
A42: 1504 | B42: LIDE3/VAOV2-RHMA3-GASH | D42: TAOAco | E42: 0710430/Coastal/10432 | F42: S407tm | G42: Tan oak/Douglas-fir moist
A43: 1501 | B43: LIDE3-ABCO/BENE2 | C43: Tanoak-Canyon Live Oak and/or Sadler Oak | D43: MEVG | E43: 0710430/Interior/10431 | F43: S408td | G43: Tan oak/Douglas-fir dry
A44: 1502 | B44: LIDE3-ACMA3-QUCH2/POMU | C44: Tanoak-Bigleaf Maple-Canyon Live Oak/Western Swordfern | D44: TAOAco | E44: 0710430/Coastal/10432 | F44: S407tm | G44: Tan oak/Douglas-fir moist
A45: 1501 | B45: LIDE3-CACH6/GASH-QUSA2 | C45: Tanoak-Canyon Live Oak and/or Sadler Oak | D45: MEVG | E45: 0710430/Interior/10431 | F45: S408td | G45: Tan oak/Douglas-fir dry
A46: 1501 | B46: LIDE3-CACH6-PILA | C46: Tanoak-Canyon Live Oak and/or Sadler Oak | D46: MEVG | E46: 0710430/Interior/10431 | F46: S408td | G46: Tan oak/Douglas-fir dry
A47: 1503 | B47: LIDE3-CHLA/GASH | C47: Tanoak/Salal | D47: TAOAco | E47: 0710430/Coastal/10432 | F47: S407tm | G47: Tan oak/Douglas-fir moist
A48: 1521 | B48: LIDE3-PIMO3/QUVA/XETE | D48: TAOAco | E48: 0710430/Coastal/10432 | F48: S407tm | G48: Tan oak/Douglas fir moist
A49: 1503 | B49: LIDE3-PSME/GASH-BENE2 | D49: TAOAco | E49: 0710430/Coastal/10432 | F49: S407tm | G49: Tan oak/Douglas-fir moist
A50: 1504 | B50: LIDE3-PSME/GASH-RHMA3 | C50: Tanoak/Evergreen Huckleberry | D50: TAOAco | E50: 0710430/Coastal/10432 | F50: S407tm | G50: Tan oak/Douglas-fir moist
A51: 1504 | B51: LIDE3-PSME/GASH-VAOV2 | D51: TAOAco | E51: 0710430/Coastal/10432 | F51: S407tm | G51: Tan oak/Douglas-fir moist
A52: 1501 | B52: LIDE3-PSME/QUSA2-BENE2 | C52: Tanoak-Canyon Live Oak and/or Sadler Oak | D52: MEVG | E52: 0710430/Interior/10431 | F52: S408td | G52: Tan oak/Douglas-fir dry
A53: 1501 | B53: LIDE3-PSME-QUCH2/BENE2 | C53: Tanoak-Canyon Live Oak and/or Sadler Oak | D53: MEVG | E53: 0710430/Interior/10431 | F53: S408td | G53: Tan oak/Douglas-fir dry
A54: 1501 | B54: LIDE3-PSME-QUCH2/RHDI6 | C54: Tanoak-Canyon Live Oak and/or Sadler Oak | D54: MEVG | E54: 0710430/Interior/10431 | F54: S408td | G54: Tan oak/Douglas-fir dry
A55: 1504 | B55: LIDE3-TSHE/VAOV2/POMU | D55: TAOAco | E55: 0710430/Coastal/10432 | F55: S407tm | G55: Tan oak/Douglas-fir moist
A56: 1504 | B56: LIDE3-TSHE/VAOV2/POMU-RIP | D56: TAOAco | E56: 0710430/Coastal/10432 | F56: S407tm | G56: Tan oak/Douglas-fir moist
A57: 1504 | B57: LIDE3-TSHE/VAOV2-RHDI6 | D57: TAOAco | E57: 0710430/Coastal/10432 | F57: S407tm | G57: Tan oak/Douglas-fir moist
A58: 801 | B58: PICO/VAME-VASC | C58: Lodgepole Pine - SWO | E58: 710580 | F58: S412lx | G58: Lodgepole pine - cold
A59: 801 | B59: PICO-ABCO-PSME | C59: Lodgepole Pine - SWO | E59: 710580 | F59: S412lx | G59: Lodgepole pine - cold
A60: 801 | B60: PICO-TSME/DEP | C60: Lodgepole Pine - SWO | E60: 710580 | F60: S412lx | G60: Lodgepole pine - cold
A61: 1201 | B61: PIJE/ARCA5/FEID | C61: Jeffrey Pine/Grass | D61: PIJEsp | E61: 710210 | F61: S404jp | G61: Jeffrey pine
A62: 1201 | B62: PIJE/CECU/FEID | C62: Jeffrey Pine/Grass | D62: PIJEsp | E62: 710210 | F62: S404jp | G62: Jeffrey pine
A63: 1201 | B63: PIJE/FEID | C63: Jeffrey Pine/Grass | D63: PIJEsp | E63: 710210 | F63: S404jp | G63: Jeffrey pine
A64: 1202 | B64: PIJE/QUVA-ARNE | C64: Jeffrey Pine/Shrub | D64: PIJEsp | E64: 710210 | F64: S404jp | G64: Jeffrey pine
A65: 1202 | B65: PIJE/QUVA-ARNE-GABU2 | C65: Jeffrey Pine/Shrub | D65: PIJEsp | E65: 710210 | F65: S404jp | G65: Jeffrey pine
A66: 1203 | B66: PIJE-CADE27/ARVI4 | C66: Jeffrey Pine-Incense Cedar | D66: PIJEsp | E66: 710210 | F66: S404jp | G66: Jeffrey pine
...

Sheet BpS SWOR
A1: Code | B1: Name | C1: Likely to be treated
A2: 10210 | B2: Klamath-Siskiyou Lower Montane Serpentine Mixed Conifer Woodland | C2: *
A3: 10270 | B3: Mediterranean California Dry-Mesic Mixed Conifer Forest and Woodland | C3: *
A4: 10280 | B4: Mediterranean California Mesic Mixed Conifer Forest and Woodland
A5: 10290 | B5: Mediterranean California Mixed Oak Woodland | C5: *
A6: 10300 | B6: Mediterranean California Lower Montane Black Oak-Conifer Forest and Woodland | C6: *
A7: 103010 | B7: California Montane Jeffrey Pine-Ponderosa Pine Woodland
A8: 10320 | B8: Mediterranean California Red Fir Forest
A9: 10321 | B9: Mediterranean California Red Fir Forest – Cascades
A10: 10370 | B10: North Pacific Maritime Dry-Mesic Douglas-fir-Western Hemlock Forest
A11: 10390 | B11: North Pacific Maritime Mesic-Wet Douglas-fir-Western Hemlock Forest
A12: 10412 | B12: North Pacific Mountain Hemlock Forest - Xeric
A13: 10431 | B13: Mediterranean California Mixed-Evergreen Forest -- Interior | C13: *
A14: 10432 | B14: Mediterranean California Mixed Evergreen Forest -- Coastal
A15: 10531 | B15: Northern Rocky Mountain Ponderosa Pine Woodland and Savanna - Mesic
A16: 10580 | B16: Sierra Nevada Subalpine Lodgepole Pine Forest and Woodland
A17: 11740 | B17: North Pacific Dry-Mesic Silver Fir-Western Hemlock-Douglas-fir Forest

Sheet BpS2013
A1: LF National BpS Model | B1: LF National BpS Name | C1: LF BpS Group Model | D1: LF BpS Group Name | E1: LF Group Model Source
A2: 110010 | B2: Inter-Mountain Basins Sparsely Vegetated Systems | C2: 100 | D2: Sparsely Vegetated | E2: No model
A3: 110030 | B3: North Pacific Sparsely Vegetated Systems | C3: 100 | D3: Sparsely Vegetated | E3: No model
A4: 110060 | B4: Rocky Mountain Alpine/Montane Sparsely Vegetated Systems | C4: 100 | D4: Sparsely Vegetated | E4: No model
A5: 110080 | B5: North Pacific Oak Woodland | C5: 118 | D5: Oregon White Oak-Romers Fescue-Oatgrass-1 | E5: 610290
A6: 110180 | B6: East Cascades Mesic Montane Mixed-Conifer Forest and Woodland | C6: 109 | D6: Douglas Fir-Grand Fir Mix-3 | E6: 110180
A7: 110350 | B7: North Pacific Dry Douglas-fir(-Madrone) Forest and Woodland | C7: 125 | D7: Douglas Fir-3 | E7: 210350
A8: 110360 | B8: North Pacific Hypermaritime Sitka Spruce Forest | C8: 126 | D8: Sitka Spruce-Western Hemlock-5 | E8: 110360
A9: 110370 | B9: North Pacific Maritime Dry-Mesic Douglas-fir-Western Hemlock Forest | C9: 127 | D9: Douglas Fir-Western Hemlock-3 | E9: 110370
A10: 110380 | B10: North Pacific Maritime Mesic Subalpine Parkland | C10: 128 | D10: Mountain Hemlock-Mountainheath-5 | E10: 110380
A11: 110390 | B11: North Pacific Maritime Mesic-Wet Douglas-fir-Western Hemlock Forest | C11: 129 | D11: Douglas Fir-Western Hemlock-5 | E11: 110390
A12: 110411 | B12: North Pacific Mountain Hemlock Forest - Wet | C12: 130 | D12: Mountain Hemlock-Devils Club-5 | E12: 110411
A13: 110412 | B13: North Pacific Mountain Hemlock Forest - Xeric | C13: 131 | D13: Mountain Hemlock-Huckleberry-5 | E13: 710412
A14: 110420 | B14: North Pacific Mesic Western Hemlock-Silver Fir Forest | C14: 132 | D14: Western Hemlock-5 | E14: 110420
A15: 110450 | B15: Northern Rocky Mountain Dry-Mesic Montane Mixed Conifer Forest | C15: 135 | D15: Ponderosa Pine-Douglas Fir-1 | E15: 910450
A16: 110460 | B16: Northern Rocky Mountain Subalpine Woodland and Parkland | C16: 139 | D16: Whitebark Pine-3 | E16: 2110460
... A101: 311770 | B101: California Coastal Closed-Cone Conifer Forest and Woodland | C101: 273 | D101: Monterey Cypress-Shore Pine-4 | E101: 411770
A102: 410040 | B102: North American Warm Desert Sparsely Vegetated Systems | C102: 100 | D102: Sparsely Vegetated | E102: No model
A103: 410140 | B103: Central and Southern California Mixed Evergreen Woodland | C103: 105 | D103: Canyon Live Oak-Coulter Pine-1 | E103: 410140
A104: 410150 | B104: California Coastal Redwood Forest | C104: 106 | D104: Redwood-1 | E104: 410150
A105: 410190 | B105: Great Basin Pinyon-Juniper Woodland | C105: 110 | D105: Singleleaf Pinyon-Utah Juniper-3 | E105: 1210190
A106: 410270 | B106: Mediterranean California Dry-Mesic Mixed Conifer Forest and Woodland | C106: 116 | D106: Ponderosa Pine-Incense Cedar-1 | E106: 410270
A107: 410280 | B107: Mediterranean California Mesic Mixed Conifer Forest and Woodland | C107: 117 | D107: Douglas Fir-White Fir-Sugar Pine-1 | E107: 410280
A108: 410290 | B108: Mediterranean California Mixed Oak Woodland | C108: 118 | D108: Oregon White Oak-Romers Fescue-Oatgrass-1 | E108: 610290
A109: 410300 | B109: Mediterranean California Lower Montane Black Oak-Conifer Forest and Woodland | C109: 119 | D109: Ponderosa Pine-California Black Oak-1 | E109: 710300
A110: 410310 | B110: California Montane Jeffrey Pine(-Ponderosa Pine) Woodland | C110: 120 | D110: Jeffrey Pine-1 | E110: 210310
A111: 410340 | B111: Mediterranean California Mesic Serpentine Woodland and Chaparral | C111: 124 | D111: Sargents Cypress-LeatherOak-3 | E111: 610340
A112: 410580 | B112: Sierra Nevada Subalpine Lodgepole Pine Forest and Woodland | C112: 158 | D112: Lodgepole Pine-3 | E112: 410580
A113: 410820 | B113: Mojave Mid-Elevation Mixed Desert Scrub | C113: 184 | D113: Blackbrush-Jointfir-5 | E113: 1310820
A114: 410870 | B114: Sonora-Mojave Creosotebush-White Bursage Desert Scrub | C114: 192 | D114: Creosote-Bursage-5 | E114: 1310870
... A137: 411770 | B137: California Coastal Closed-Cone Conifer Forest and Woodland | C137: 273 | D137: Monterey Cypress-Shore Pine-4 | E137: 411770
A138: 510010 | B138: Inter-Mountain Basins Sparsely Vegetated Systems | C138: 100 | D138: Sparsely Vegetated | E138: No model
A139: 510020 | B139: Mediterranean California Sparsely Vegetated Systems | C139: 100 | D139: Sparsely Vegetated | E139: No model
A140: 510140 | B140: Central and Southern California Mixed Evergreen Woodland | C140: 105 | D140: Canyon Live Oak-Coulter Pine-1 | E140: 410140
A141: 510270 | B141: Mediterranean California Dry-Mesic Mixed Conifer Forest and Woodland | C141: 116 | D141: Ponderosa Pine-Incense Cedar-1 | E141: 410270
A142: 510290 | B142: Mediterranean California Mixed Oak Woodland | C142: 118 | D142: Oregon White Oak-Romers Fescue-Oatgrass-1 | E142: 610290
A143: 510300 | B143: Mediterranean California Lower Montane Black Oak-Conifer Forest and Woodland | C143: 119 | D143: Ponderosa Pine-California Black Oak-1 | E143: 710300
A144: 510310 | B144: California Montane Jeffrey Pine(-Ponderosa Pine) Woodland | C144: 120 | D144: Jeffrey Pine-1 | E144: 210310
A145: 510430 | B145: Mediterranean California Mixed Evergreen Forest | C145: 133 | D145: Douglas Fir-Tanoak-Pacific Madrone-1 | E145: 310430
A146: 510880 | B146: Sonora-Mojave Mixed Salt Desert Scrub | C146: 183 | D146: Shadscale-Winterfat-5 | E146: 1210810
...

Sheet Deleted - SWOR_PA_PVT_SDI
A1: PlantAssociations | B1: Series | C1: PVT | D1: SDImax | E1: Climate adaptive density target species | F1: Number of plots | G1: Comment
A2: LIDE3-QUCH/BENE | B2: =LEFT(A2,4) -> LIDE | C2: Tan oak - Douglas-fir - Dry | D2: NA | F2: 2 | G2: DELETE AND REASSIGN PLOTS, not in blue book, "draft PA"
A3: LIDE3-TSHE/VAOV2-RHDI6 | B3: =LEFT(A3,4) -> LIDE | C3: Tan oak - Douglas-fir - Moist | D3: NA | F3: 5 | G3: DELETE AND REASSIGN PLOTS, not in blue book, "draft PA"
A4: ABCO-CADE3/BENE | B4: =LEFT(A4,4) -> ABCO | C4: White fir - Intermediate | D4: 561 | E4: PILA | G4: DELETE from domain
A5: ABAM/VAAL/POMU | B5: =LEFT(A5,4) -> ABAM | C5: Pacific silver fir - Intermediate | D5: 755 | E5: ABMAS | G5: DELETE, not in blue book
A6: ABAM/VAME | B6: =LEFT(A6,4) -> ABAM | C6: Pacific silver fir - Intermediate | D6: 755 | E6: ABMAS | G6: DELETE, not in blue book
A7: ABAM/VAME/CLUN | B7: =LEFT(A7,4) -> ABAM | C7: Pacific silver fir - Intermediate | D7: 755 | E7: ABMAS | G7: DELETE, not in blue book
A8: ABAM/VAME/XETE | B8: =LEFT(A8,4) -> ABAM | C8: Pacific silver fir - Intermediate | D8: 755 | E8: ABMAS | G8: DELETE, not in blue book
A9: ABAM-TSME/CLUN | B9: =LEFT(A9,4) -> ABAM | C9: Pacific silver fir - Intermediate | D9: 755 | E9: ABMAS | G9: DELETE, not in blue book
A10: ABGR/ACCI/ACTR | B10: =LEFT(A10,4) -> ABGR | C10: White fir - Warm moist | D10: 750 | E10: ABMAS | G10: DELETE, not in blue book
A11: ABGR/ACCI/POMU | B11: =LEFT(A11,4) -> ABGR | C11: White fir - Warm moist | D11: 750 | E11: ABMAS | G11: DELETE, not in blue book
A12: ABGR/BENE2-GASH | B12: =LEFT(A12,4) -> ABGR | C12: White fir - Warm moist | D12: 750 | E12: ABMAS | G12: DELETE, not in blue book
A13: ABGR/CACH | B13: =LEFT(A13,4) -> ABGR | C13: White fir - Cool | D13: 750 | E13: ABMAS | G13: DELETE, not in blue book
A14: ABGR/CHUM | B14: =LEFT(A14,4) -> ABGR | C14: White fir - Cool | D14: 750 | E14: ABMAS | G14: DELETE, not in blue book
A15: ABGR/COCO6/VAHE | B15: =LEFT(A15,4) -> ABGR | C15: White fir - Warm moist | D15: 750 | E15: ABMAS | G15: DELETE, not in blue book
... A35: PICO-CAREX-LUPINUS | B35: =LEFT(A35,4) -> PICO | C35: Lodgepole pine - Cold | D35: 400 | E35: PICO | G35: DELETE, not in blue book
A36: PIMO3-PICO/LIDEE-RHMA3 | B36: =LEFT(A36,5) -> PIMO3 | D36: 460 | E36: PIMO3 | G36: DELETE, not in blue book
A37: PIMO3-PSME/QUVA-LIDEE | B37: =LEFT(A37,5) -> PIMO3 | C37: Ultramafic, cold | D37: 460 | E37: PIMO3 | G37: DELETE, not in blue book
A38: PIPO/PUTR/CAPE-PUM | B38: =LEFT(A38,4) -> PIPO | C38: Ponderosa pine - Dry | D38: 499 | E38: PIPO | G38: DELETE, not in blue book
A39: PIPO/PUTR/FEID-PUMICE | B39: =LEFT(A39,4) -> PIPO | C39: Ponderosa pine - Dry | D39: 499 | E39: PIPO | G39: DELETE, not in blue book
A40: PIPO/PUTR-ARTR/FEID | B40: =LEFT(A40,4) -> PIPO | C40: Ponderosa pine - Dry | D40: 499 | E40: PIPO | G40: DELETE, not in blue book
A41: PIPO/PUTR-CEVE/STOC-PUM | B41: =LEFT(A41,4) -> PIPO | C41: Ponderosa pine - Dry | D41: 499 | E41: PIPO | G41: DELETE, not in blue book
A42: PSME/BERE | B42: =LEFT(A42,4) -> PSME | C42: Douglas-fir - Moist | D42: 499 | E42: PIPO | G42: DELETE, not in blue book
A43: PSME/COCO6-SYMO/POMU | B43: =LEFT(A43,4) -> PSME | C43: Douglas-fir - Moist | D43: 499 | E43: PIPO | G43: DELETE, not in blue book
A44: PSME/HODI-SYMPH | B44: =LEFT(A44,4) -> PSME | C44: Douglas-fir - Dry | D44: 499 | E44: PIPO | G44: DELETE, not in blue book
A45: PSME/MANE2 | B45: =LEFT(A45,4) -> PSME | C45: Douglas-fir - Dry | D45: 499 | E45: PIPO | G45: DELETE, not in blue book
A46: PSME/MANE2-GASH | B46: =LEFT(A46,4) -> PSME | C46: Douglas-fir - Moist | D46: 499 | E46: PIPO | G46: DELETE, not in blue book
A47: PSME/QUVA-RHMA3 | B47: =LEFT(A47,4) -> PSME | C47: Douglas-fir - Dry | D47: 499 | E47: PIPO | G47: DELETE, not in blue book
A48: PSME/RHMA3-VAOV2 | B48: =LEFT(A48,4) -> PSME | C48: Douglas-fir - Moist | D48: 499 | E48: PIPO | G48: DELETE, not in blue book
A49: PSME/TODI | B49: =LEFT(A49,4) -> PSME | C49: Douglas-fir - Dry | D49: 499 | E49: PIPO | G49: DELETE, not in blue book
... A92: TSHE-LIDE3/RHMA3-VAOV2 | B92: =LEFT(A92,4) -> TSHE | C92: Tan oak - Douglas-fir - Moist | D92: 600 | E92: PSME | G92: DELETE, not in blue book
A93: ABCO, ABGR | B93: =LEFT(A93,4) -> ABCO | C93: White fir - Cool | D93: 750 | G93: DELETE, not in blue book
A94: ABCO/CACH-CEVE/CAIN9 | B94: =LEFT(A94,4) -> ABCO | C94: White fir - Intermediate | D94: 530 | G94: DELETE, not in blue book
A95: ABCO/CEVE-CACH | B95: =LEFT(A95,4) -> ABCO | C95: White fir - Intermediate | D95: 530 | G95: DELETE, not in blue book
A96: ABCO/CEVE-CEPR/FRVI | B96: =LEFT(A96,4) -> ABCO | C96: White fir - Cool | D96: 750 | G96: DELETE, not in blue book
A97: ABCO-ABGR/ASCA3 | B97: =LEFT(A97,4) -> ABCO | C97: White fir - Cool | D97: 750 | G97: DELETE, not in blue book
A98: ABCO-ABGR/CHUM | B98: =LEFT(A98,4) -> ABCO | C98: White fir - Cool | D98: 750 | G98: DELETE, not in blue book
A99: ABCO-ABGR/LIBO2 | B99: =LEFT(A99,4) -> ABCO | C99: White fir - Cool | D99: 750 | G99: DELETE, not in blue book
A100: ABCO-ARPA6-ARNE2/CAIN9 | B100: =LEFT(A100,4) -> ABCO | C100: White fir - Intermediate | D100: 530 | G100: DELETE, not in blue book
A101: ABCO-CACH6/PAMY/CHUM | B101: =LEFT(A101,4) -> ABCO | C101: White fir - Cool | D101: 750 | G101: DELETE, not in blue book
...
